<robot name="onshape">
<link name="world"/>
<link name="prismatic_x"/>
<link name="prismatic_y"/>
<link name="linkBase">
<visual>
<origin xyz="0.0185 -3.46325e-18 0" rpy="0 -0 -3.96508e-16" />
<geometry>
<mesh filename="package://baselink.stl"/>
</geometry>
<material name="baselink_material">
<color rgba="0.654902 0.823529 0.576471 1.0"/>
</material>
</visual>
<collision>
<origin xyz="0.0185 -3.46325e-18 0" rpy="0 -0 -3.96508e-16" />
<geometry>
<mesh filename="package://baselink.stl"/>
</geometry>
<material name="baselink_material">
<color rgba="0.654902 0.823529 0.576471 1.0"/>
</material>
</collision>
<inertial>
<origin xyz="0 0 0" rpy="0 0 0"/>
<mass value="0" />
<inertia ixx="0" ixy="0"  ixz="0" iyy="0" iyz="0" izz="0" />
</inertial>
</link>

<link name="link0">
<visual>
<origin xyz="3.85186e-34 0 -0.00625" rpy="0 -0 1.5708" />
<geometry>
<mesh filename="package://midlink.stl"/>
</geometry>
<material name="midlink_material">
<color rgba="0.141176 0.694118 0.65098 1.0"/>
</material>
</visual>
<collision>
<origin xyz="3.85186e-34 0 -0.00625" rpy="0 -0 1.5708" />
<geometry>
<mesh filename="package://midlink.stl"/>
</geometry>
<material name="midlink_material">
<color rgba="0.141176 0.694118 0.65098 1.0"/>
</material>
</collision>
<inertial>
<origin xyz="0 0.0497183 -0.00634236" rpy="0 0 0"/>
<mass value="0.643789" />
<inertia ixx="0.000694903" ixy="0"  ixz="0" iyy="9.60358e-05" iyz="0" izz="0.000724384" />
</inertial>
</link>

<link name="link1">
<visual>
<origin xyz="0 0 -0.00625" rpy="0 -0 1.5708" />
<geometry>
<mesh filename="package://midlink.stl"/>
</geometry>
<material name="midlink_material">
<color rgba="0.141176 0.694118 0.65098 1.0"/>
</material>
</visual>
<collision>
<origin xyz="0 0 -0.00625" rpy="0 -0 1.5708" />
<geometry>
<mesh filename="package://midlink.stl"/>
</geometry>
<material name="midlink_material">
<color rgba="0.141176 0.694118 0.65098 1.0"/>
</material>
</collision>
<inertial>
<origin xyz="0 0.0497183 -0.00634236" rpy="0 0 0"/>
<mass value="0.643789" />
<inertia ixx="0.000694903" ixy="0"  ixz="0" iyy="9.60358e-05" iyz="0" izz="0.000724384" />
</inertial>
</link>

<link name="link2">
<visual>
<origin xyz="3.08149e-33 -0.1 -0.00625" rpy="0 -0 1.5708" />
<geometry>
<mesh filename="package://endlink.stl"/>
</geometry>
<material name="endlink_material">
<color rgba="0.141176 0.694118 0.65098 1.0"/>
</material>
</visual>
<collision>
<origin xyz="3.08149e-33 -0.1 -0.00625" rpy="0 -0 1.5708" />
<geometry>
<mesh filename="package://endlink.stl"/>
</geometry>
<material name="endlink_material">
<color rgba="0.141176 0.694118 0.65098 1.0"/>
</material>
</collision>
<inertial>
<origin xyz="0 0.0439482 -0.00625" rpy="0 0 0"/>
<mass value="0.58676" />
<inertia ixx="0.000481409" ixy="0"  ixz="0" iyy="9.10293e-05" iyz="0" izz="0.000503074" />
</inertial>
</link>

<link name="linkEE">
<visual>
<origin xyz="-6.23416e-18 -1.41172e-18 0.192436" rpy="1.5708 1.5708 0" />
<geometry>
<mesh filename="package://eelink.stl"/>
</geometry>
<material name="eelink_material">
<color rgba="1 0 0 1.0"/>
</material>
</visual>
<collision>
<origin xyz="-6.23416e-18 -1.41172e-18 0.192436" rpy="1.5708 1.5708 0" />
<geometry>
<mesh filename="package://eelink.stl"/>
</geometry>
<material name="eelink_material">
<color rgba="1 0 0 1.0"/>
</material>
</collision>
<inertial>
<origin xyz="0 0 0" rpy="0 0 0"/>
<mass value="0" />
<inertia ixx="0" ixy="0"  ixz="0" iyy="0" iyz="0" izz="0" />
</inertial>
</link>

<joint name="jointEE" type="floating">
<origin xyz="-6.14381e-18 0.0924356 -0.00625" rpy="-1.5708 -9.09944e-18 3.14159" />
<parent link="link2" />
<child link="linkEE" />
<axis xyz="0 0 1"/>
<limit effort="1" velocity="20" />
<joint_properties friction="0.0"/>
</joint>

<joint name="joint2" type="revolute">
<origin xyz="1.39635e-17 0.1 0" rpy="-5.92223e-33 7.16446e-32 9.66355e-30" />
<parent link="link1" />
<child link="link2" />
<axis xyz="0 0 1"/>
<limit effort="1" velocity="20" />
<joint_properties friction="0.0"/>
</joint>

<joint name="joint1" type="revolute">
<origin xyz="1.42993e-19 0.1 -1.73472e-17" rpy="-3.27028e-20 -6.8592e-18 -7.93016e-18" />
<parent link="link0" />
<child link="link1" />
<axis xyz="0 0 1"/>
<limit effort="1" velocity="20" />
<joint_properties friction="0.0"/>
</joint>

<joint name="joint0" type="revolute">
<origin xyz="0.0185 -3.46945e-18 0.00625" rpy="1.66824e-26 -1.77123e-27 -1.5708" />
<parent link="linkBase" />
<child link="link0" />
<axis xyz="0 0 1"/>
<limit effort="1" velocity="20" />
<joint_properties friction="0.0"/>
</joint>

<joint name="world2px" type="fixed">
<origin xyz="0 -0.01750000 0" rpy="0 0 0" />
<parent link="world" />
<child link="prismatic_x" />
</joint>

<joint name="px2py" type="prismatic">
<origin xyz="0 0 0" rpy="0 0 0" />
<axis xyz="1 0 0"/>
<parent link="prismatic_x" />
<child link="prismatic_y" />
<limit effort="1" velocity="20" />
<joint_properties friction="0.0"/>
</joint>

<joint name="py2base" type="prismatic">
<origin xyz="0 0 0" rpy="0 0 1.57079632679" />
<axis xyz="1 0 0"/>
<parent link="prismatic_y" />
<child link="linkBase" />
<limit effort="1" velocity="20" />
<joint_properties friction="0.0"/>
</joint>

</robot>
